Workbook

Sheet 3.
C2: Distâncias entre Clientes e Centro de Distribuição de Espanha
E4: 41.3300,-1.2200 | F4: 39.2577,-7.9310 | G4: 37.4545,-7.8724 | H4: 40.2112,-8.4101 | I4: 40.9285,-8.5484 | J4: 41.7546,-7.4734 | K4: 41.8081,-6.7676 | L4: 43.3637,-5.8489 | M4: 39.8682,-4.0266 | N4: 39.4767,-0.3759 | O4: 41.6525,-0.8890 | P4: 41.3906,2.1721
C5: Distância (km) | D5: id | E5: Espanha - Saragoça | F5: Évora | G5: Faro | H5: Coimbra | I5: Santa Maria da Feira | J5: Chaves | K5: Bragança | L5: Oviedo | M5: Toledo | N5: Valência | O5: Saragoça | P5: Barcelona
E6: 27 | F6: 3 | G6: 4 | H6: 5 | I6: 6 | J6: 7 | K6: 8 | L6: 9 | M6: 10 | N6: 11 | O6: 12 | P6: 13
B7: 41.3300,-1.2200 | C7: Espanha - Saragoça | D7: 27 | E7: 0 | F7: 789 | G7: 912 | H7: 764 | I7: 783 | J7: 645 | K7: 545 | L7: 576 | M7: 356 | N7: 263 | O7: 54.3 | P7: 359
B8: 39.2577,-7.9310 | C8: Évora | D8: 3 | E8: =F7 -> 789 | F8: 0 | G8: 262 | H8: 158 | I8: 251 | J8: 398 | K8: 365 | L8: 657 | M8: 465 | N8: 760 | O8: 817 | P8: 1123
B9: 37.4545,-7.8724 | C9: Faro | D9: 4 | E9: =G7 -> 912 | F9: =G8 -> 262 | G9: 0 | H9: 410 | I9: 502 | J9: 683 | K9: 623 | L9: 858 | M9: 591 | N9: 864 | O9: 942 | P9: 1209
B10: 40.2112,-8.4101 | C10: Coimbra | D10: 5 | E10: =H7 -> 764 | F10: =H8 -> 158 | G10: =H9 -> 410 | H10: 0 | I10: 94.6 | J10: 242 | K10: 287 | L10: 608 | M10: 483 | N10: 853 | O10: 792 | P10: 1098
B11: 40.9285,-8.5484 | C11: Santa Maria da Feira | D11: 6 | E11: =I7 -> 783 | F11: =I8 -> 251 | G11: =I9 -> 502 | H11: =I10 -> 94.6 | I11: 0 | J11: 241 | K11: 286 | L11: 607 | M11: 551 | N11: 886 | O11: 810 | P11: 1116
B12: 41.7546,-7.4734 | C12: Chaves | D12: 7 | E12: =J7 -> 645 | F12: =J8 -> 398 | G12: =J9 -> 683 | H12: =J10 -> 242 | I12: =J11 -> 241 | J12: 0 | K12: 111 | L12: 372 | M12: 520 | N12: 812 | O12: 670 | P12: 976
B13: 41.8081,-6.7676 | C13: Bragança | D13: 8 | E13: =K7 -> 545 | F13: =K8 -> 365 | G13: =K9 -> 623 | H13: =K10 -> 287 | I13: =K11 -> 286 | J13: =K12 -> 111 | K13: 0 | L13: 327 | M13: 415 | N13: 715 | O13: 573 | P13: 879
B14: 43.3637,-5.8489 | C14: Oviedo | D14: 9 | E14: =L7 -> 576 | F14: =L8 -> 657 | G14: =L9 -> 858 | H14: =L10 -> 608 | I14: =L11 -> 607 | J14: =L12 -> 372 | K14: =L13 -> 327 | L14: 0 | M14: 524 | N14: 816 | O14: 544 | P14: 869
B15: 39.8682,-4.0266 | C15: Toledo | D15: 10 | E15: =M7 -> 356 | F15: =M8 -> 465 | G15: =M9 -> 591 | H15: =M10 -> 483 | I15: =M11 -> 551 | J15: =M12 -> 520 | K15: =M13 -> 415 | L15: =M14 -> 524 | M15: 0 | N15: 391 | O15: 382 | P15: 686
B16: 39.4767,-0.3759 | C16: Valência | D16: 11 | E16: =N7 -> 263 | F16: =N8 -> 760 | G16: =N9 -> 864 | H16: =N10 -> 853 | I16: =N11 -> 886 | J16: =N12 -> 812 | K16: =N13 -> 715 | L16: =N14 -> 816 | M16: =N15 -> 391 | N16: 0 | O16: 318 | P16: 366
B17: 41.6525,-0.8890 | C17: Saragoça | D17: 12 | E17: =O7 -> 54.3 | F17: =O8 -> 817 | G17: =O9 -> 942 | H17: =O10 -> 792 | I17: =O11 -> 810 | J17: =O12 -> 670 | K17: =O13 -> 573 | L17: =O14 -> 544 | M17: =O15 -> 382 | N17: =O16 -> 318 | O17: 0 | P17: 306
B18: 41.3906,2.1721 | C18: Barcelona | D18: 13 | E18: =P7 -> 359 | F18: =P8 -> 1123 | G18: =P9 -> 1209 | H18: =P10 -> 1098 | I18: =P11 -> 1116 | J18: =P12 -> 976 | K18: =P13 -> 879 | L18: =P14 -> 869 | M18: =P15 -> 686 | N18: =P16 -> 366 | O18: =P17 -> 306 | P18: 0
C20: Pressupostos: | D20: As distâncias (km) foram obtidas através do Google Maps. Foi tida em conta a distância real sem portagens (para não acrescer custo).
C23: Tempo percorrido entre Clientes e Centro de Distribuição de Espanha
C25: Tempo (min) | D25: id | E25: Espanha - Saragoça | F25: Évora | G25: Faro | H25: Coimbra | I25: Santa Maria da Feira | J25: Chaves | K25: Bragança | L25: Oviedo | M25: Toledo | N25: Valência | O25: Saragoça | P25: Barcelona
E26: 27 | F26: 3 | G26: 4 | H26: 5 | I26: 6 | J26: 7 | K26: 8 | L26: 9 | M26: 10 | N26: 11 | O26: 12 | P26: 13
C27: Espanha - Saragoça | D27: 27 | E27: 0 | F27: =8*60+9 -> 489 | G27: =9*60+58 -> 598 | H27: =8*60+51 -> 531 | I27: =8*60+57 -> 537 | J27: =7*60 -> 420 | K27: =6*60+20 -> 380 | L27: =6*60+38 -> 398 | M27: =3*60+50 -> 230 | N27: =2*60+48 -> 168 | O27: 44 | P27: =3*60+53 -> 233
C28: Évora | D28: 3 | E28: =F27 -> 489 | F28: 0 | G28: =3*60+27 -> 207 | H28: =60+56 -> 116 | I28: =3*60+18 -> 198 | J28: =4*60+29 -> 269 | K28: =4*60+2 -> 242 | L28: =7*60+19 -> 439 | M28: =5*60+1 -> 301 | N28: =8*60+31 -> 511 | O28: =8*60+31 -> 511 | P28: =11*60+33 -> 693
C29: Faro | D29: 4 | E29: =G27 -> 598 | F29: =G28 -> 207 | G29: 0 | H29: =5*60+13 -> 313 | I29: =6*60+34 -> 394 | J29: =7*60+38 -> 458 | K29: =7*60+9 -> 429 | L29: =9*60+59 -> 599 | M29: =6*60+37 -> 397 | N29: =9*60+12 -> 552 | O29: =10*60+19 -> 619 | P29: =12*60+42 -> 762
C30: Coimbra | D30: 5 | E30: =H27 -> 531 | F30: =H28 -> 116 | G30: =H29 -> 313 | H30: 0 | I30: =60+31 -> 91 | J30: =2*60+45 -> 165 | K30: =3*60+29 -> 209 | L30: =6*60+26 -> 386 | M30: =5*60+30 -> 330 | N30: =9*60+14 -> 554 | O30: =8*60+44 -> 524 | P30: =11*60+45 -> 705
C31: Santa Maria da Feira | D31: 6 | E31: =I27 -> 537 | F31: =I28 -> 198 | G31: =I29 -> 394 | H31: =I30 -> 91 | I31: 0 | J31: =2*60+45 -> 165 | K31: =3*60+28 -> 208 | L31: =6*60+39 -> 399 | M31: =6*60+7 -> 367 | N31: =9*60+25 -> 565 | O31: =8*60+49 -> 529 | P31: =11*60+49 -> 709
C32: Chaves | D32: 7 | E32: =J27 -> 420 | F32: =J28 -> 269 | G32: =J29 -> 458 | H32: =J30 -> 165 | I32: =J31 -> 165 | J32: 0 | K32: =60+32 -> 92 | L32: =4*60+19 -> 259 | M32: =5*60+34 -> 334 | N32: =8*60+36 -> 516 | O32: =7*60+14 -> 434 | P32: =10*60+19 -> 619
C33: Bragança | D33: 8 | E33: =K27 -> 380 | F33: =K28 -> 242 | G33: =K29 -> 429 | H33: =K30 -> 209 | I33: =K31 -> 208 | J33: =K32 -> 92 | K33: 0 | L33: =4*60+3 -> 243 | M33: =4*60+41 -> 281 | N33: =7*60+51 -> 471 | O33: =6*60+27 -> 387 | P33: =9*60+37 -> 577
C34: Oviedo | D34: 9 | E34: =L27 -> 398 | F34: =L28 -> 439 | G34: =L29 -> 599 | H34: =L30 -> 386 | I34: =L31 -> 399 | J34: =L32 -> 259 | K34: =L33 -> 243 | L34: 0 | M34: =5*60+55 -> 355 | N34: =8*60+54 -> 534 | O34: =6*60+23 -> 383 | P34: =9*60+33 -> 573
C35: Toledo | D35: 10 | E35: =M27 -> 230 | F35: =M28 -> 301 | G35: =M29 -> 397 | H35: =M30 -> 330 | I35: =M31 -> 367 | J35: =M32 -> 334 | K35: =M33 -> 281 | L35: =M34 -> 355 | M35: 0 | N35: =4*60 -> 240 | O35: =3*60+56 -> 236 | P35: =7*60+7 -> 427
C36: Valência | D36: 11 | E36: =N27 -> 168 | F36: =N28 -> 511 | G36: =N29 -> 552 | H36: =N30 -> 554 | I36: =N31 -> 565 | J36: =N32 -> 516 | K36: =N33 -> 471 | L36: =N34 -> 534 | M36: =N35 -> 240 | N36: 0 | O36: =3*60+36 -> 216 | P36: =4*60+6 -> 246
C37: Saragoça | D37: 12 | E37: =O27 -> 44 | F37: =O28 -> 511 | G37: =O29 -> 619 | H37: =O30 -> 524 | I37: =O31 -> 529 | J37: =O32 -> 434 | K37: =O33 -> 387 | L37: =O34 -> 383 | M37: =O35 -> 236 | N37: =O36 -> 216 | O37: 0 | P37: =3*60+27 -> 207
C38: Barcelona | D38: 13 | E38: =P27 -> 233 | F38: =P28 -> 693 | G38: =P29 -> 762 | H38: =P30 -> 705 | I38: =P31 -> 709 | J38: =P32 -> 619 | K38: =P33 -> 577 | L38: =P34 -> 573 | M38: =P35 -> 427 | N38: =P36 -> 246 | O38: =P37 -> 207 | P38: 0
C41: Procura Diária do Produto A e B dos Clientes
C43: Procura | E43: Évora | F43: Faro | G43: Coimbra | H43: Santa Maria da Feira | I43: Chaves | J43: Bragança | K43: Oviedo | L43: Toledo | M43: Valência | N43: Saragoça | O43: Barcelona
E44: 3 | F44: 4 | G44: 5 | H44: 6 | I44: 7 | J44: 8 | K44: 9 | L44: 10 | M44: 11 | N44: 12 | O44: 13
C45: Produto A (Kg) | E45: ='[1]0. DADOS'!K7*100*1000/'3.'!$F$53*I55 -> 9597.73 | F45: ='[1]0. DADOS'!K8*100*1000/'3.'!$F$53*I55 -> 12796.973 | G45: ='[1]0. DADOS'!K9*100*1000/'3.'!$F$53*$I$55 -> 15996.217 | H45: ='[1]0. DADOS'!K10*100*1000/'3.'!$F$53*$I$55 -> 6398.4867 | I45: ='[1]0. DADOS'!K11*100*1000/'3.'!$F$53*I55 -> 9597.73 | J45: ='[1]0. DADOS'!K12*100*1000/'3.'!$F$53*$I$55 -> 3199.2433 | K45: ='[1]0. DADOS'!K13*100*1000/'3.'!$F$53*$I$55 -> 7998.1084 | L45: ='[1]0. DADOS'!K14*100*1000/'3.'!$F$53*$I$55 -> 7998.1084 | M45: ='[1]0. DADOS'!K15*100*1000/'3.'!$F$53*I55 -> 23994.325 | N45: ='[1]0. DADOS'!K16*100*1000/'3.'!$F$53*I55 -> 23994.325 | O45: ='[1]0. DADOS'!K17*100*1000/'3.'!$F$53*I55 -> 31992.433
C46: Produto B (Kg) | E46: ='[1]0. DADOS'!K7*100*1000/'3.'!$F$53*J55 -> 1765.9063 | F46: ='[1]0. DADOS'!K8*100*1000/'3.'!$F$53*J55 -> 2354.5418 | G46: ='[1]0. DADOS'!K9*100*1000/'3.'!$F$53*J55 -> 2943.1772 | H46: ='[1]0. DADOS'!K10*100*1000/'3.'!$F$53*J55 -> 1177.2709 | I46: ='[1]0. DADOS'!K11*100*1000/'3.'!$F$53*J55 -> 1765.9063 | J46: ='[1]0. DADOS'!K12*100*1000/'3.'!$F$53*J55 -> 588.63544 | K46: ='[1]0. DADOS'!K13*100*1000/'3.'!$F$53*J55 -> 1471.5886 | L46: ='[1]0. DADOS'!K14*100*1000/'3.'!$F$53*J55 -> 1471.5886 | M46: ='[1]0. DADOS'!K15*100*1000/'3.'!$F$53*J55 -> 4414.7658 | N46: ='[1]0. DADOS'!K16*100*1000/'3.'!$F$53*J55 -> 4414.7658 | O46: ='[1]0. DADOS'!K17*100*1000/'3.'!$F$53*J55 -> 5886.3544
C47: Total Diário (Kg) | E47: =SUM(E45:E46) -> 11363.636 | F47: =SUM(F45:F46) -> 15151.515 | G47: =SUM(G45:G46) -> 18939.394 | H47: =SUM(H45:H46) -> 7575.7576 | I47: =SUM(I45:I46) -> 11363.636 | J47: =SUM(J45:J46) -> 3787.8788 | K47: =SUM(K45:K46) -> 9469.697 | L47: =SUM(L45:L46) -> 9469.697 | ... O47: =SUM(O45:O46) -> 37878.788
C48: Total Mensal (Kg) | E48: =E47*22 -> 250000 | F48: =F47*22 -> 333333.33 | G48: =G47*22 -> 416666.67 | H48: =H47*22 -> 166666.67 | I48: =I47*22 -> 250000 | J48: =J47*22 -> 83333.333 | K48: =K47*22 -> 208333.33 | L48: =L47*22 -> 208333.33 | ... O48: =O47*22 -> 833333.33
C49: Total Anual (Kg) | E49: =E48*12 -> 3000000 | F49: =F48*12 -> 4000000 | G49: =G48*12 -> 5000000 | H49: =H48*12 -> 2000000 | I49: =I48*12 -> 3000000 | J49: =J48*12 -> 1000000 | K49: =K48*12 -> 2500000 | L49: =L48*12 -> 2500000 | ... O49: =O48*12 -> 10000000
...
